Workbook
Name profit: Sheet1!$N:$N

Sheet Sheet3

Sheet Sheet1
A1: order_id | B1: region | C1: category | D1: sales | E1: sales category | F1: discount | G1: Discount Amount | H1: Final Amount | I1: quantity | J1: order_date | K1: delivery_date | L1: customer_type | M1: payment_mode | N1: profit | O1: profit category | P1: city
A2: ORD100000 | B2: East | C2: Clothing | D2: 713.49 | E2: =IF(D2>800,"Good Sales","concerning") -> concerning | F2: 0.31 | G2: =D2*F2 -> 221.1819 | H2: =D2-G2 -> 492.3081 | I2: 3 | J2: 45015 | K2: 45017 | L2: Member | M2: UPI | N2: 114.72 | O2: =IF(N2>800,"profit","loss") -> loss | P2: Pune
A3: ORD100001 | B3: West | C3: Electronics | D3: 3802.97 | E3: =IF(D3>800,"Good Sales","concerning") -> Good Sales | F3: 0.38 | G3: =D3*F3 -> 1445.1286 | H3: =D3-G3 -> 2357.8414 | I3: 4 | J3: 45166 | K3: 45172 | L3: Regular | M3: Card | N3: 971.41 | O3: =IF(N3>800,"profit","loss") -> profit | P3: Hyderabad
A4: ORD100002 | B4: North | C4: Home Care | D4: 3588.97 | E4: =IF(D4>800,"Good Sales","concerning") -> Good Sales | F4: 0.1 | G4: =D4*F4 -> 358.897 | H4: =D4-G4 -> 3230.073 | I4: 7 | J4: 45360 | K4: 45366 | L4: Regular | M4: Cash | N4: 769.08 | O4: =IF(N4>800,"profit","loss") -> loss | P4: Bangalore
A5: ORD100003 | B5: East | C5: Electronics | D5: 1160.86 | E5: =IF(D5>800,"Good Sales","concerning") -> Good Sales | F5: 0.27 | G5: =D5*F5 -> 313.4322 | H5: =D5-G5 -> 847.4278 | I5: 5 | J5: 45578 | K5: 45584 | L5: Member | M5: UPI | N5: 71.61 | O5: =IF(N5>800,"profit","loss") -> loss | P5: Pune
A6: ORD100004 | B6: East | C6: Electronics | D6: 3071.32 | E6: =IF(D6>800,"Good Sales","concerning") -> Good Sales | F6: 0 | G6: =D6*F6 -> 0 | H6: =D6-G6 -> 3071.32 | I6: 7 | J6: 45022 | K6: 45025 | L6: New | M6: Cash | N6: 621.92 | O6: =IF(N6>800,"profit","loss") -> loss | P6: Bangalore
A7: ORD100005 | B7: West | C7: Grocery | D7: 2566.18 | E7: =IF(D7>800,"Good Sales","concerning") -> Good Sales | F7: 0.02 | G7: =D7*F7 -> 51.3236 | H7: =D7-G7 -> 2514.8564 | I7: 6 | J7: 45108 | K7: 45111 | L7: Member | M7: UPI | N7: 578.94 | O7: =IF(N7>800,"profit","loss") -> loss | P7: Mumbai
A8: ORD100006 | B8: North | C8: Personal Care | D8: 398 | E8: =IF(D8>800,"Good Sales","concerning") -> concerning | F8: 0.16 | G8: =D8*F8 -> 63.68 | H8: =D8-G8 -> 334.32 | I8: 4 | J8: 45119 | K8: 45124 | L8: New | M8: Cash | N8: 110.31 | O8: =IF(N8>800,"profit","loss") -> loss | P8: Mumbai
A9: ORD100007 | B9: North | C9: Personal Care | D9: 1462.95 | E9: =IF(D9>800,"Good Sales","concerning") -> Good Sales | F9: 0.23 | G9: =D9*F9 -> 336.4785 | H9: =D9-G9 -> 1126.4715 | I9: 2 | J9: 45064 | K9: 45066 | L9: Regular | M9: UPI | N9: 91.68 | O9: =IF(N9>800,"profit","loss") -> loss | P9: Bangalore
A10: ORD100008 | B10: East | C10: Personal Care | D10: 4997.47 | E10: =IF(D10>800,"Good Sales","concerning") -> Good Sales | F10: 0.29 | G10: =D10*F10 -> 1449.2663 | H10: =D10-G10 -> 3548.2037 | I10: 6 | J10: 45296 | K10: 45299 | L10: Regular | M10: Card | N10: 995.78 | O10: =IF(N10>800,"profit","loss") -> profit | P10: Delhi
A11: ORD100009 | B11: South | C11: Grocery | D11: 587.72 | E11: =IF(D11>800,"Good Sales","concerning") -> concerning | F11: 0.44 | G11: =D11*F11 -> 258.5968 | H11: =D11-G11 -> 329.1232 | I11: 6 | J11: 45514 | K11: 45521 | L11: New | M11: Cash | N11: 102.96 | O11: =IF(N11>800,"profit","loss") -> loss | P11: Pune
A12: ORD100010 | B12: East | C12: Clothing | D12: 2581.42 | E12: =IF(D12>800,"Good Sales","concerning") -> Good Sales | F12: 0.39 | G12: =D12*F12 -> 1006.7538 | H12: =D12-G12 -> 1574.6662 | I12: 6 | J12: 45419 | K12: 45420 | L12: Regular | M12: Cash | N12: 542.82 | O12: =IF(N12>800,"profit","loss") -> loss | P12: Bangalore | R12: =SUM(R1534) -> 0
A13: ORD100011 | B13: East | C13: Clothing | D13: 4261.74 | E13: =IF(D13>800,"Good Sales","concerning") -> Good Sales | F13: 0.15 | G13: =D13*F13 -> 639.261 | H13: =D13-G13 -> 3622.479 | I13: 1 | J13: 45171 | K13: 45172 | L13: New | M13: UPI | N13: 1028.47 | O13: =IF(N13>800,"profit","loss") -> profit | P13: Pune
A14: ORD100012 | B14: East | C14: Home Care | D14: 1573.19 | E14: =IF(D14>800,"Good Sales","concerning") -> Good Sales | F14: 0.37 | G14: =D14*F14 -> 582.0803 | H14: =D14-G14 -> 991.1097 | I14: 6 | J14: 45331 | K14: 45338 | L14: New | M14: Cash | N14: 131.5 | O14: =IF(N14>800,"profit","loss") -> loss | P14: Bangalore | R14: Total Customer
A15: ORD100013 | B15: East | C15: Clothing | D15: 1377.47 | E15: =IF(D15>800,"Good Sales","concerning") -> Good Sales | F15: 0.27 | G15: =D15*F15 -> 371.9169 | H15: =D15-G15 -> 1005.5531 | I15: 2 | J15: 45074 | K15: 45075 | L15: Member | M15: Cash | N15: 255.49 | O15: =IF(N15>800,"profit","loss") -> loss | P15: Delhi | R15: =COUNT(N1:N15346) -> 15345
A16: ORD100014 | B16: West | C16: Clothing | D16: 4464.89 | E16: =IF(D16>800,"Good Sales","concerning") -> Good Sales | F16: 0.39 | G16: =D16*F16 -> 1741.3071 | H16: =D16-G16 -> 2723.5829 | I16: 5 | J16: 45296 | K16: 45303 | L16: Regular | M16: UPI | N16: 804.36 | O16: =IF(N16>800,"profit","loss") -> profit | P16: Pune
A17: ORD100015 | B17: North | C17: Personal Care | D17: 1593.67 | E17: =IF(D17>800,"Good Sales","concerning") -> Good Sales | F17: 0.21 | G17: =D17*F17 -> 334.6707 | H17: =D17-G17 -> 1258.9993 | I17: 7 | J17: 45583 | K17: 45587 | L17: Member | M17: Card | N17: 284.91 | O17: =IF(N17>800,"profit","loss") -> loss | P17: Chennai
A18: ORD100016 | B18: West | C18: Electronics | D18: 3292.32 | E18: =IF(D18>800,"Good Sales","concerning") -> Good Sales | F18: 0.05 | G18: =D18*F18 -> 164.616 | H18: =D18-G18 -> 3127.704 | I18: 1 | J18: 45042 | K18: 45043 | L18: Member | M18: Card | N18: 504.83 | O18: =IF(N18>800,"profit","loss") -> loss | P18: Mumbai
A19: ORD100017 | B19: West | C19: Clothing | D19: 3727.53 | E19: =IF(D19>800,"Good Sales","concerning") -> Good Sales | F19: 0.31 | G19: =D19*F19 -> 1155.5343 | H19: =D19-G19 -> 2571.9957 | I19: 5 | J19: 45228 | K19: 45235 | L19: Regular | M19: Card | N19: 978.07 | O19: =IF(N19>800,"profit","loss") -> profit | P19: Chennai
A20: ORD100018 | B20: West | C20: Clothing | D20: 3964.23 | E20: =IF(D20>800,"Good Sales","concerning") -> Good Sales | F20: 0.28 | G20: =D20*F20 -> 1109.9844 | H20: =D20-G20 -> 2854.2456 | I20: 9 | J20: 45448 | K20: 45451 | L20: Member | M20: UPI | N20: 260.95 | O20: =IF(N20>800,"profit","loss") -> loss | P20: Bangalore
A21: ORD100019 | B21: East | C21: Grocery | D21: 4974.32 | E21: =IF(D21>800,"Good Sales","concerning") -> Good Sales | F21: 0.48 | G21: =D21*F21 -> 2387.6736 | H21: =D21-G21 -> 2586.6464 | I21: 3 | J21: 45047 | K21: 45051 | L21: Regular | M21: Card | N21: 727.29 | O21: =IF(N21>800,"profit","loss") -> loss | P21: Delhi
A22: ORD100020 | B22: South | C22: Home Care | D22: 4035.64 | E22: =IF(D22>800,"Good Sales","concerning") -> Good Sales | F22: 0.08 | G22: =D22*F22 -> 322.8512 | H22: =D22-G22 -> 3712.7888 | I22: 2 | J22: 45586 | K22: 45593 | L22: Regular | M22: Cash | N22: 798.81 | O22: =IF(N22>800,"profit","loss") -> loss | P22: Delhi | R22: =SUM(N1:N15346) -> 6872139.8
A23: ORD100021 | B23: North | C23: Grocery | D23: 3319.36 | E23: =IF(D23>800,"Good Sales","concerning") -> Good Sales | F23: 0.33 | G23: =D23*F23 -> 1095.3888 | H23: =D23-G23 -> 2223.9712 | I23: 2 | J23: 45153 | K23: 45159 | L23: Member | M23: Cash | N23: 920.22 | O23: =IF(N23>800,"profit","loss") -> profit | P23: Bangalore
A24: ORD100022 | B24: South | C24: Personal Care | D24: 4487.77 | E24: =IF(D24>800,"Good Sales","concerning") -> Good Sales | F24: 0.24 | G24: =D24*F24 -> 1077.0648 | H24: =D24-G24 -> 3410.7052 | I24: 3 | J24: 45657 | K24: 45659 | L24: Regular | M24: Card | N24: 931.37 | O24: =IF(N24>800,"profit","loss") -> profit | P24: Pune | R24: profit
A25: ORD100023 | B25: West | C25: Electronics | D25: 4538.15 | E25: =IF(D25>800,"Good Sales","concerning") -> Good Sales | F25: 0.19 | G25: =D25*F25 -> 862.2485 | H25: =D25-G25 -> 3675.9015 | I25: 1 | J25: 45005 | K25: 45008 | L25: Regular | M25: Cash | N25: 375.7 | O25: =IF(N25>800,"profit","loss") -> loss | P25: Delhi | R25: =SUMIF(O2:O15346,"profit",profit) -> 1084495
A26: ORD100024 | B26: West | C26: Home Care | D26: 4868.52 | E26: =IF(D26>800,"Good Sales","concerning") -> Good Sales | F26: 0.4 | G26: =D26*F26 -> 1947.408 | H26: =D26-G26 -> 2921.112 | I26: 2 | J26: 45272 | K26: 45273 | L26: Regular | M26: Cash | N26: 1072.26 | O26: =IF(N26>800,"profit","loss") -> profit | P26: Mumbai
A27: ORD100025 | B27: South | C27: Grocery | D27: 3904.68 | E27: =IF(D27>800,"Good Sales","concerning") -> Good Sales | F27: 0.41 | G27: =D27*F27 -> 1600.9188 | H27: =D27-G27 -> 2303.7612 | I27: 6 | J27: 45066 | K27: 45072 | L27: Regular | M27: Card | N27: 526.66 | O27: =IF(N27>800,"profit","loss") -> loss | P27: Hyderabad
A28: ORD100026 | B28: South | C28: Clothing | D28: 1055.14 | E28: =IF(D28>800,"Good Sales","concerning") -> Good Sales | F28: 0.36 | G28: =D28*F28 -> 379.8504 | H28: =D28-G28 -> 675.2896 | I28: 8 | J28: 45462 | K28: 45468 | L28: Member | M28: UPI | N28: 207.61 | O28: =IF(N28>800,"profit","loss") -> loss | P28: Chennai | R28: count
A29: ORD100027 | B29: South | C29: Clothing | D29: 3578.05 | E29: =IF(D29>800,"Good Sales","concerning") -> Good Sales | F29: 0.04 | G29: =D29*F29 -> 143.122 | H29: =D29-G29 -> 3434.928 | I29: 4 | J29: 45215 | K29: 45217 | L29: New | M29: Card | N29: 689.74 | O29: =IF(N29>800,"profit","loss") -> loss | P29: Mumbai | R29: =COUNTIF(O1:O15346,"profit") -> 2444
A30: ORD100028 | B30: West | C30: Home Care | D30: 468.13 | E30: =IF(D30>800,"Good Sales","concerning") -> concerning | F30: 0.17 | G30: =D30*F30 -> 79.5821 | H30: =D30-G30 -> 388.5479 | I30: 2 | J30: 45255 | K30: 45261 | L30: Member | M30: UPI | N30: 43.58 | O30: =IF(N30>800,"profit","loss") -> loss | P30: Hyderabad | R30: =COUNTIF(O1:O15346,"loss") -> 12901
A31: ORD100029 | B31: West | C31: Clothing | D31: 1658.02 | E31: =IF(D31>800,"Good Sales","concerning") -> Good Sales | F31: 0.02 | G31: =D31*F31 -> 33.1604 | H31: =D31-G31 -> 1624.8596 | I31: 5 | J31: 45356 | K31: 45357 | L31: New | M31: Cash | N31: 422.33 | O31: =IF(N31>800,"profit","loss") -> loss | P31: Delhi
A32: ORD100030 | B32: North | C32: Grocery | D32: 667.46 | E32: =IF(D32>800,"Good Sales","concerning") -> concerning | F32: 0.17 | G32: =D32*F32 -> 113.4682 | H32: =D32-G32 -> 553.9918 | I32: 3 | J32: 45026 | K32: 45031 | L32: New | M32: Card | N32: 123.49 | O32: =IF(N32>800,"profit","loss") -> loss | P32: Pune
A33: ORD100031 | B33: North | C33: Grocery | D33: 4754.72 | E33: =IF(D33>800,"Good Sales","concerning") -> Good Sales | F33: 0.32 | G33: =D33*F33 -> 1521.5104 | H33: =D33-G33 -> 3233.2096 | I33: 5 | J33: 45527 | K33: 45531 | L33: New | M33: Cash | N33: 697.03 | O33: =IF(N33>800,"profit","loss") -> loss | P33: Chennai | R33: Row Labels | S33: Sum of sales | T33: Sum of profit
A34: ORD100032 | B34: West | C34: Clothing | D34: 1759.9 | E34: =IF(D34>800,"Good Sales","concerning") -> Good Sales | F34: 0.26 | G34: =D34*F34 -> 457.574 | H34: =D34-G34 -> 1302.326 | I34: 3 | J34: 44933 | K34: 44939 | L34: Regular | M34: Cash | N34: 178.58 | O34: =IF(N34>800,"profit","loss") -> loss | P34: Delhi | R34: East | S34: 9518321.9 | T34: 1675277.8
A35: ORD100033 | B35: South | C35: Clothing | D35: 3594.76 | E35: =IF(D35>800,"Good Sales","concerning") -> Good Sales | F35: 0.35 | G35: =D35*F35 -> 1258.166 | H35: =D35-G35 -> 2336.594 | I35: 4 | J35: 45097 | K35: 45099 | L35: New | M35: UPI | N35: 1002.97 | O35: =IF(N35>800,"profit","loss") -> profit | P35: Delhi | R35: North | S35: 10143913 | T35: 1769020.9
A36: ORD100034 | B36: South | C36: Personal Care | D36: 2899.46 | E36: =IF(D36>800,"Good Sales","concerning") -> Good Sales | F36: 0.28 | G36: =D36*F36 -> 811.8488 | H36: =D36-G36 -> 2087.6112 | I36: 5 | J36: 45189 | K36: 45190 | L36: Regular | M36: Cash | N36: 320.43 | O36: =IF(N36>800,"profit","loss") -> loss | P36: Bangalore | R36: South | S36: 9851779.2 | T36: 1714039
A37: ORD100035 | B37: North | C37: Electronics | D37: 626.81 | E37: =IF(D37>800,"Good Sales","concerning") -> concerning | F37: 0.28 | G37: =D37*F37 -> 175.5068 | H37: =D37-G37 -> 451.3032 | I37: 7 | J37: 45298 | K37: 45303 | L37: Regular | M37: UPI | N37: 177.84 | O37: =IF(N37>800,"profit","loss") -> loss | P37: Mumbai | R37: West | S37: 9748863.1 | T37: 1713802.1
A38: ORD100036 | B38: West | C38: Home Care | D38: 2850.59 | E38: =IF(D38>800,"Good Sales","concerning") -> Good Sales | F38: 0.26 | G38: =D38*F38 -> 741.1534 | H38: =D38-G38 -> 2109.4366 | I38: 2 | J38: 45470 | K38: 45474 | L38: Regular | M38: Card | N38: 528.38 | O38: =IF(N38>800,"profit","loss") -> loss | P38: Chennai | R38: (blank)
A39: ORD100037 | B39: North | C39: Grocery | D39: 3339.02 | E39: =IF(D39>800,"Good Sales","concerning") -> Good Sales | F39: 0.18 | G39: =D39*F39 -> 601.0236 | H39: =D39-G39 -> 2737.9964 | I39: 6 | J39: 45651 | K39: 45652 | L39: Member | M39: Cash | N39: 586.69 | O39: =IF(N39>800,"profit","loss") -> loss | P39: Hyderabad | R39: Grand Total | S39: 39262878 | T39: 6872139.8
A40: ORD100038 | B40: North | C40: Home Care | D40: 4419.43 | E40: =IF(D40>800,"Good Sales","concerning") -> Good Sales | F40: 0.22 | G40: =D40*F40 -> 972.2746 | H40: =D40-G40 -> 3447.1554 | I40: 6 | J40: 45423 | K40: 45426 | L40: New | M40: UPI | N40: 742.22 | O40: =IF(N40>800,"profit","loss") -> loss | P40: Pune
...

Sheet Sheet2
A1: KPI
A2: max profit | B2: =MAX(Sheet1!N2:N15346) -> 1486.66
A3: min profit | B3: =MIN(Sheet1!N:N) -> 5.76
A4: avrage profit | B4: =AVERAGE(profit) -> 447.84228
A7: max sales | B7: =MAX(Sheet1!D1:D15346) -> 4999.87
A8: min sales | B8: =MIN(Sheet1!D:D) -> 100.1
A9: avrage sales | B9: =AVERAGE(Sheet1!D2:D15346) -> 2558.6756
A10: total sales | B10: =SUM(Sheet1!D2:D15346) -> 39262878
A11: count sales | B11: =COUNT(Sheet1!D:D) -> 15345
A12: countsales
D15347: {=avrage(Sheet1!D15347)} -> #NAME?
